<mujoco model="NaoH25V50">
  <!--<option timestep="0.01"/>-->
  <option timestep="0.001" iterations="100" solver="Newton"/>
  <!--<option gravity="0 0 0"/>-->
  <default>
  <geom contype="0" conaffinity="0"
        solref="0.002 1"
        solimp="0.9 0.95 0.001"/>
  <default class="body_geom">
  <geom
    type="box"
    contype="0"
    conaffinity="0"
    friction="0.3 0.01 0.001"
    rgba="0.6 0.6 0.6 1"/>
  </default>

  <default class="foot_geom">
    <geom
      type="box"
      contype="1"
      conaffinity="1"
      friction="2.0 0.1 0.05"
      rgba="0.2 0.2 0.8 1"/>
  </default>

  <joint damping="0.5"/>
  </default>

  <compiler angle="radian"/>

  <worldbody>
  <camera name="main_cam" pos="3 0 1.5"/>

  <geom name="floor" type="plane" size="5 5 0.1" rgba="0.8 0.8 0.8 1" contype="1"
      conaffinity="1"/>
  <light pos="0 0 3"/>

  <body name="base" pos="0 0 0.34">
  <inertial
    pos="-0.00413 0 0.04342"
    mass="1.0496"
    diaginertia="0.005 0.005 0.005"/>
  <geom class="body_geom" size="0.05 0.05 0.1" rgba="0.8 0.2 0.2 1"/>
  <joint type="free" damping="1"/>
    <body name="Neck" pos="0 0 0.1265">
      <inertial pos="-1e-05 0 -0.02742" quat="0.70765 -0.00173495 0.00151894 0.706559" mass="0.07842" diaginertia="1.70396e-05 1.60324e-05 5.53348e-06"/>
      <joint name="HeadYaw" pos="0 0 0" axis="0 0 1" range="-2.08567 2.08567" actuatorfrcrange="-1.547 1.547"/>
      <body name="Head">
        <inertial pos="-0.00112 0 0.05258" quat="0.463877 0.585354 -0.492966 0.446277" mass="0.60533" diaginertia="0.000990592 0.000957952 0.000811033"/>
        <joint name="HeadPitch" pos="0 0 0" axis="0 1 0" range="-0.671952 0.514872" actuatorfrcrange="-1.532 1.532"/>
        <geom class="body_geom" size="0.02 0.03 0.02" pos="0 0 0.01" rgba="0.2 0.2 0.8 1"/>
      </body>
    </body>
    <body name="LPelvis" pos="0 0.05 -0.085">
      <inertial pos="-0.00781 -0.01114 0.02661" quat="0.232303 0.656505 0.182148 0.69416" mass="0.06981" diaginertia="5.16414e-05 4.58792e-05 2.32239e-05"/>
      <joint name="LHipYawPitch" pos="0 0 0" axis="0 0.707107 -0.707107" range="-1.14529 0.740718" actuatorfrcrange="-3.348 3.348"/>
      <body name="LHip">
        <inertial pos="-0.01549 0.00029 -0.00515" quat="0.453959 0.527953 0.574067 0.430853" mass="0.14053" diaginertia="6.08587e-05 5.59269e-05 2.22526e-05"/>
        <joint name="LHipRoll" pos="0 0 0" axis="1 0 0" range="-0.379435 0.79046" actuatorfrcrange="-3.348 3.348"/>
        <body name="LThigh">
          <inertial pos="0.00138 0.00221 -0.05373" quat="0.992078 -0.0228023 -0.123519 -0.00190301" mass="0.38968" diaginertia="0.000524114 0.000465732 0.000286453"/>
          <joint name="LHipPitch" pos="0 0 0" axis="0 1 0" range="-1.53589 0.48398" actuatorfrcrange="-3.023 3.023"/>
          <geom class="body_geom" size="0.03 0.03 0.05" pos="0 0 -0.05" rgba="0.2 0.2 0.8 1"/>
          <body name="LTibia" pos="0 0 -0.1">
            <inertial pos="0.00453 0.00225 -0.04936" quat="0.997907 0.0169027 0.0579417 0.0232071" mass="0.30142" diaginertia="0.000449928 0.000388139 0.000181704"/>
            <joint name="LKneePitch" pos="0 0 0" axis="0 1 0" range="-0.0923279 2.11255" actuatorfrcrange="-3.023 3.023"/>
            <geom class="body_geom" size="0.025 0.025 0.05145" pos="0 0 -0.05145" rgba="0.2 0.8 0.2 1"/>
            <body name="LAnklePitch" pos="0 0 -0.1029">
              <inertial pos="0.00045 0.00029 0.00685" quat="0.447256 0.548803 0.537287 0.458368" mass="0.13416" diaginertia="6.79494e-05 5.56016e-05 3.14223e-05"/>
              <joint name="LAnklePitch" pos="0 0 0" axis="0 1 0" range="-1.18944 0.922581" actuatorfrcrange="-3.023 3.023"/>
              <body name="l_ankle">
                <inertial pos="0.0254198 0.00330005 -0.0323906" quat="0.0134363 0.704739 -0.00974782 0.709273" mass="0.171848" diaginertia="0.000412891 0.000353334 8.70025e-05"/>
                <joint name="LAnkleRoll" pos="0 0 0" axis="1 0 0" range="-0.397761 0.768992" actuatorfrcrange="-3.348 3.348"/>
                <geom class="foot_geom" type="box" size="0.06 0.025 0.02259" pos="0.02 0 -0.02259" rgba="0.2 0.2 0.8 1"/>
              </body>
            </body>
          </body>
        </body>
      </body>
    </body>
    <body name="RPelvis" pos="0 -0.05 -0.085">
      <inertial pos="-0.00781 0.01114 0.02661" quat="-0.286295 0.637526 -0.200888 0.686469" mass="0.06981" diaginertia="6.0003e-05 4.60859e-05 3.15895e-05"/>
      <joint name="RHipYawPitch" pos="0 0 0" axis="0 0.707107 0.707107" range="-1.14529 0.740718" actuatorfrcrange="-3.348 3.348"/>
      <body name="RHip">
        <inertial pos="-0.01549 -0.00029 -0.00515" quat="0.431269 0.573083 0.528698 0.453941" mass="0.14053" diaginertia="6.08554e-05 5.59208e-05 2.2268e-05"/>
        <joint name="RHipRoll" pos="0 0 0" axis="1 0 0" range="-0.79046 0.379435" actuatorfrcrange="-3.348 3.348"/>
        <body name="RThigh">
          <inertial pos="0.00138 -0.00221 -0.05373" quat="0.99203 0.0205489 -0.124311 0.000726212" mass="0.38968" diaginertia="0.000525121 0.000466802 0.000286518"/>
          <joint name="RHipPitch" pos="0 0 0" axis="0 1 0" range="-1.53589 0.48398" actuatorfrcrange="-3.0226 3.0226"/>
          <geom class="body_geom" size="0.03 0.03 0.05" pos="0 0 -0.05" rgba="0.2 0.2 0.8 1"/>
          <body name="RTibia" pos="0 0 -0.1">
            <inertial pos="0.00453 -0.00225 -0.04936" quat="0.99698 -0.0149083 0.0724691 -0.0235809" mass="0.30142" diaginertia="0.000452851 0.000387699 0.000177824"/>
            <joint name="RKneePitch" pos="0 0 0" axis="0 1 0" range="-0.0923279 2.11255" actuatorfrcrange="-3.0226 3.0226"/>
            <geom class="body_geom" size="0.025 0.025 0.05145" pos="0 0 -0.05145" rgba="0.2 0.8 0.2 1"/>
            <body name="RAnklePitch" pos="0 0 -0.1029">
              <inertial pos="0.00045 -0.00029 0.00685" quat="0.458219 0.537985 0.54818 0.447332" mass="0.13416" diaginertia="6.79942e-05 5.56532e-05 3.14175e-05"/>
              <joint name="RAnklePitch" pos="0 0 0" axis="0 1 0" range="-1.1863 0.932006" actuatorfrcrange="-3.0226 3.0226"/>
              <body name="r_ankle">
                <inertial pos="0.0254198 -0.00330005 -0.0323906" quat="-0.0138336 0.704473 0.00894574 0.70954" mass="0.171848" diaginertia="0.000412175 0.000352454 8.68701e-05"/>
                <joint name="RAnkleRoll" pos="0 0 0" axis="1 0 0" range="-0.768992 0.397761" actuatorfrcrange="-3.348 3.348"/>
                <geom class="foot_geom" type="box" size="0.06 0.025 0.02259" pos="0.02 0 -0.02259" rgba="0.2 0.2 0.8 1"/>
              </body>
            </body>
          </body>
        </body>
      </body>
    </body>
    <body name="LShoulder" pos="0 0.098 0.1">
      <inertial pos="-0.00165 -0.02663 0.00014" quat="0.353499 0.572853 -0.442525 0.592494" mass="0.09304" diaginertia="2.02186e-05 1.91002e-05 1.30704e-05"/>
      <joint name="LShoulderPitch" pos="0 0 0" axis="0 1 0" range="-2.08567 2.08567" actuatorfrcrange="-1.329 1.329"/>
      <body name="LBicep">
        <inertial pos="0.02455 0.00563 0.0033" quat="0.467645 0.46185 0.492756 0.570257" mass="0.15777" diaginertia="0.00027823 0.000242894 8.25818e-05"/>
        <joint name="LShoulderRoll" pos="0 0 0" axis="0 0 1" range="-0.314159 1.32645" actuatorfrcrange="-1.7835 1.7835"/>
        <geom class="body_geom" size="0.05 0.02 0.02" pos="0.05 0 0" rgba="0.2 0.2 0.8 1"/>
        <body name="LElbow" pos="0.105 0.015 0">
          <inertial pos="-0.02744 0 -0.00014" quat="-0.000545392 0.711779 -0.000696018 0.702403" mass="0.06483" diaginertia="2.76333e-05 2.66179e-05 5.592e-06"/>
          <joint name="LElbowYaw" pos="0 0 0" axis="1 0 0" range="-2.08567 2.08567" actuatorfrcrange="-1.547 1.547"/>
          <body name="LForeArm">
            <inertial pos="0.02556 0.00281 0.00076" quat="0.481839 0.619088 0.422287 0.454131" mass="0.07761" diaginertia="3.9183e-05 3.6083e-05 2.37632e-05"/>
            <joint name="LElbowRoll" pos="0 0 0" axis="0 0 1" range="-1.54462 -0.0349066" actuatorfrcrange="-1.532 1.532"/>
            <geom class="body_geom" size="0.028 0.02 0.02" pos="0.028 0 0" rgba="0.2 0.8 0.2 1"/>
            <body name="l_wrist" pos="0.05595 0 0">
              <inertial pos="0.03434 -0.00088 0.00308" quat="0.346526 0.607704 0.329318 0.634165" mass="0.18533" diaginertia="0.000137482 0.000131631 6.85194e-05"/>
              <joint name="LWristYaw" pos="0 0 0" axis="1 0 0" range="-1.82387 1.82387" actuatorfrcrange="-0.4075 0.4075"/>
              <geom class="body_geom" size="0.028 0.02 0.02" pos="0.028 0 0" rgba="0.2 0.2 0.8 1"/>
            </body>
          </body>
        </body>
      </body>
    </body>
    <body name="RShoulder" pos="0 -0.098 0.1">
      <inertial pos="-0.00165 0.02663 0.00014" quat="0.572853 0.353499 -0.592494 0.442525" mass="0.09304" diaginertia="2.02186e-05 1.91002e-05 1.30704e-05"/>
      <joint name="RShoulderPitch" pos="0 0 0" axis="0 1 0" range="-2.08567 2.08567" actuatorfrcrange="-1.329 1.329"/>
      <body name="RBicep">
        <inertial pos="0.02455 -0.00563 0.0033" quat="0.556969 0.570609 0.359404 0.484788" mass="0.15777" diaginertia="0.000287934 0.00025515 8.56154e-05"/>
        <joint name="RShoulderRoll" pos="0 0 0" axis="0 0 1" range="-1.32645 0.314159" actuatorfrcrange="-1.783 1.783"/>
        <geom class="body_geom" size="0.05 0.02 0.02" pos="0.05 0 0" rgba="0.2 0.2 0.8 1"/>
        <body name="RElbow" pos="0.105 -0.015 0">
          <inertial pos="-0.02744 0 -0.00014" quat="-0.000545392 0.711779 -0.000696018 0.702403" mass="0.06483" diaginertia="2.76333e-05 2.66179e-05 5.592e-06"/>
          <joint name="RElbowYaw" pos="0 0 0" axis="1 0 0" range="-2.08567 2.08567" actuatorfrcrange="-1.547 1.547"/>
          <body name="RForeArm">
            <inertial pos="0.02556 -0.00281 0.00076" quat="0.453039 0.428011 0.593606 0.509111" mass="0.07761" diaginertia="3.92326e-05 3.59586e-05 2.39457e-05"/>
            <joint name="RElbowRoll" pos="0 0 0" axis="0 0 1" range="0.0349066 1.54462" actuatorfrcrange="-1.532 1.532"/>
            <geom class="body_geom" size="0.028 0.02 0.02" pos="0.028 0 0" rgba="0.2 0.8 0.2 1"/>
            <body name="r_wrist" pos="0.05595 0 0">
              <inertial pos="0.03434 0.00088 0.00308" quat="0.422432 0.617987 0.303847 0.589339" mass="0.18533" diaginertia="0.000139307 0.000131711 6.66137e-05"/>
              <joint name="RWristYaw" pos="0 0 0" axis="1 0 0" range="-1.82387 1.82387" actuatorfrcrange="-0.4075 0.4075"/>
              <geom class="body_geom" size="0.028 0.02 0.02" pos="0.028 0 0" rgba="0.2 0.2 0.8 1"/>
            </body>
          </body>
        </body>
      </body>
    </body>
  </body>
  </worldbody>

  <actuator>
  <motor name="HeadYaw" joint="HeadYaw" gear="1"/>
  <motor name="HeadPitch" joint="HeadPitch" gear="1"/>

  <motor name="LHipYawPitch"     joint="LHipYawPitch"     gear="1"/>
  <motor name="LHipRoll"    joint="LHipRoll"    gear="1"/>
  <motor name="LHipPitch"    joint="LHipPitch"    gear="1"/>
  <motor name="LKneePitch"   joint="LKneePitch"   gear="1"/>
  <motor name="LAnklePitch"  joint="LAnklePitch"  gear="1"/>
  <motor name="LAnkleRoll"   joint="LAnkleRoll"   gear="1"/>

  <motor name="RHipYawPitch"     joint="RHipYawPitch"     gear="1"/>
  <motor name="RHipRoll"    joint="RHipRoll"    gear="1"/>
  <motor name="RHipPitch"    joint="RHipPitch"    gear="1"/>
  <motor name="RKneePitch"   joint="RKneePitch"   gear="1"/>
  <motor name="RAnklePitch"  joint="RAnklePitch"  gear="1"/>
  <motor name="RAnkleRoll"   joint="RAnkleRoll"   gear="1"/>

  <motor name="LShoulderPitch"   joint="LShoulderPitch"   gear="1"/>
  <motor name="LShoulderRoll"   joint="LShoulderRoll"   gear="1"/>
  <motor name="LElbowRoll"   joint="LElbowRoll"   gear="1"/>
  <motor name="LElbowYaw"   joint="LElbowYaw"   gear="1"/>
  <motor name="LWristYaw"   joint="LWristYaw"   gear="1"/>

  <motor name="RShoulderPitch"   joint="RShoulderPitch"   gear="1"/>
  <motor name="RShoulderRoll"   joint="RShoulderRoll"   gear="1"/>
  <motor name="RElbowRoll"   joint="RElbowRoll"   gear="1"/>
  <motor name="RElbowYaw"   joint="RElbowYaw"   gear="1"/>
  <motor name="RWristYaw"   joint="RWristYaw"   gear="1"/>
  </actuator>
</mujoco>
